Workbook

Sheet Main
A1: CustomerID | B1: Income | C1: Inycome Segment | D1: MntTotal | E1: Spending Segment | F1: PctIncome | G1: Kidhome | H1: Teenhome | I1: Recency | J1: MntWines | K1: MntFruits | L1: MntMeatProducts | M1: MntFishProducts | N1: MntSweetProducts | O1: MntGoldProds | P1: TotalOfProducts | Q1: Pct_Wines | R1: Pct_Fruits | S1: Pct_Meat | T1: Pct_Fish | U1: Pct_SweetProducts | V1: Pct_GoldProducts | W1: NumDealsPurchases | X1: NumWebPurchases | Y1: NumCatalogPurchases | Z1: NumStorePurchases | AA1: TotalNumberPurchases | AB1: Pct_Deals | AC1: Pct_Web | AD1: Pct_Catalog | AE1: Pct_Store | AF1: NumWebVisitsMonth | AG1: AcceptedCmp1 | AH1: AcceptedCmp2 | AI1: AcceptedCmp3 | AJ1: AcceptedCmp4 | AK1: AcceptedCmp5 | AL1: Complain | AM1: AcceptedCmp6 | AN1: Age | AO1: AgeGroup | AP1: Customer_Days | AQ1: marital_Divorced | AR1: marital_Married | AS1: marital_Single | AT1: marital_Together | AU1: marital_Widow | AV1: education_2n Cycle | AW1: education_Graduation | AX1: education_Master | AY1: education_PhD | AZ1: MntRegularProds | BA1: DateJoined | BB1: MonthJoined | BC1: MonthName | BD1: Frequency | BE1: Helper Column
A2: 1153 | B2: 87679 | C2: =IF(B2<=AVERAGE(B:B),"Low income", "High income") -> High income | D2: 2491 | E2: =IF(D2<=AVERAGE(D:D),"Low spender", "High spender") -> High spender | F2: =D2/B2 -> 0.028410452 | G2: 0 | H2: 0 | I2: 62 | J2: 1259 | K2: 172 | L2: 815 | M2: 97 | N2: 148 | O2: 33 | P2: =SUM(J2:O2) -> 2524 | Q2: =IF(P2=0,0,J2/P2) -> 0.49881141 | R2: =IF(P2=0,0,K2/P2) -> 0.0681458 | S2: =IF(P2=0,0,L2/P2) -> 0.32290016 | T2: =IF(P2=0,0,M2/P2) -> 0.038431062 | U2: =IF(P2=0,0,N2/P2) -> 0.058637084 | V2: =IF(P2=0,0,O2/P2) -> 0.013074485 | W2: 1 | X2: 7 | Y2: 11 | Z2: 10 | AA2: =SUM(W2:Z2) -> 29 | AB2: =IF(AA2=0,0,W2/AA2) -> 0.034482759 | AC2: =IF(AA2=0,0,X2/AA2) -> 0.24137931 | AD2: =IF(AA2=0,0,Y2/AA2) -> 0.37931034 | AE2: =IF(AA2=0,0,Z2/AA2) -> 0.34482759 | AF2: 4 | AG2: 1 | AH2: 0 | AI2: 1 | AJ2: 0 | AK2: 1 | AL2: 0 | AM2: 1 | AN2: 32 | AO2: =IF(AND(AN2<36,AN2>23), "24-35", IF(AND(AN2<51,AN2>35), "36-50", IF(AND(AN2<66,AN2>50), "50-65", IF(AN2>65, "66+", "N") ))) -> 24-35 | AP2: 2496 | AQ2: 0 | AR2: 0 | AS2: 0 | AT2: 1 | AU2: 0 | AV2: 0 | AW2: 1 | AX2: 0 | AY2: 0 | AZ2: 2458 | BA2: 42353 | BB2: =MONTH(BA2) -> 12 | BC2: =TEXT(BA2,"mmmm") -> December | BD2: 1 | BE2: =_xlfn.TEXTJOIN(",",TRUE,A2:AZ2) -> 1153,87679,High income,2491,High spender,0.0284104517615393,0,0,62,1259,172,815,97,148,33,2524,0.498811410459588,0.0681458003169572,0.322900158478605,0.0384310618066561,0.0586370839936609,0.0130744849445325,1,7,11,10,29,0.0344827586206897,0.241379310344828,0.379310344827586,0.344827586206897,4,1,0,1,0,1,0,1,32,24-35,2496,0,0,0,1,0,0,1,0,0,2458
A3: 834 | B3: 3502 | C3: =IF(B3<=AVERAGE(B:B),"Low income", "High income") -> Low income | D3: 911 | E3: =IF(D3<=AVERAGE(D:D),"Low spender", "High spender") -> High spender | F3: =D3/B3 -> 0.26013706 | G3: 1 | H3: 0 | I3: 56 | J3: 2 | K3: 1 | L3: 1 | M3: 0 | N3: 0 | O3: 1 | P3: =SUM(J3:O3) -> 5 | Q3: =IF(P3=0,0,J3/P3) -> 0.4 | R3: =IF(P3=0,0,K3/P3) -> 0.2 | S3: =IF(P3=0,0,L3/P3) -> 0.2 | T3: =IF(P3=0,0,M3/P3) -> 0 | U3: =IF(P3=0,0,N3/P3) -> 0 | V3: =IF(P3=0,0,O3/P3) -> 0.2 | W3: 0 | X3: 0 | Y3: 0 | Z3: 0 | AA3: =SUM(W3:Z3) -> 0 | AB3: =IF(AA3=0,0,W3/AA3) -> 0 | AC3: =IF(AA3=0,0,X3/AA3) -> 0 | AD3: =IF(AA3=0,0,Y3/AA3) -> 0 | AE3: =IF(AA3=0,0,Z3/AA3) -> 0 | AF3: 14 | AG3: 0 | AH3: 0 | AI3: 0 | AJ3: 0 | AK3: 0 | AL3: 0 | AM3: 0 | AN3: 47 | AO3: =IF(AND(AN3<36,AN3>23), "24-35", IF(AND(AN3<51,AN3>35), "36-50", IF(AND(AN3<66,AN3>50), "50-65", IF(AN3>65, "66+", "N") ))) -> 36-50 | AP3: 2601 | AQ3: 0 | AR3: 0 | AS3: 1 | AT3: 0 | AU3: 0 | AV3: 0 | AW3: 1 | AX3: 0 | AY3: 0 | AZ3: 3 | BA3: 42248 | BB3: =MONTH(BA3) -> 9 | BC3: =TEXT(BA3,"mmmm") -> September | BD3: 1 | BE3: =_xlfn.TEXTJOIN(",",TRUE,A3:AZ3) -> 834,3502,Low income,911,High spender,0.260137064534552,1,0,56,2,1,1,0,0,1,5,0.4,0.2,0.2,0,0,0.2,0,0,0,0,0,0,0,0,0,14,0,0,0,0,0,0,0,47,36-50,2601,0,0,1,0,0,0,1,0,0,3
A4: 2180 | B4: 4861 | C4: =IF(B4<=AVERAGE(B:B),"Low income", "High income") -> Low income | D4: 2429 | E4: =IF(D4<=AVERAGE(D:D),"Low spender", "High spender") -> High spender | F4: =D4/B4 -> 0.49969142 | G4: 0 | H4: 0 | I4: 20 | J4: 2 | K4: 1 | L4: 1 | M4: 1 | N4: 0 | O4: 1 | P4: =SUM(J4:O4) -> 6 | Q4: =IF(P4=0,0,J4/P4) -> 0.33333333 | R4: =IF(P4=0,0,K4/P4) -> 0.16666667 | S4: =IF(P4=0,0,L4/P4) -> 0.16666667 | T4: =IF(P4=0,0,M4/P4) -> 0.16666667 | U4: =IF(P4=0,0,N4/P4) -> 0 | V4: =IF(P4=0,0,O4/P4) -> 0.16666667 | W4: 0 | X4: 0 | Y4: 0 | Z4: 0 | AA4: =SUM(W4:Z4) -> 0 | AB4: =IF(AA4=0,0,W4/AA4) -> 0 | AC4: =IF(AA4=0,0,X4/AA4) -> 0 | AD4: =IF(AA4=0,0,Y4/AA4) -> 0 | AE4: =IF(AA4=0,0,Z4/AA4) -> 0 | AF4: 14 | AG4: 0 | AH4: 0 | AI4: 0 | AJ4: 0 | AK4: 0 | AL4: 0 | AM4: 0 | AN4: 55 | AO4: =IF(AND(AN4<36,AN4>23), "24-35", IF(AND(AN4<51,AN4>35), "36-50", IF(AND(AN4<66,AN4>50), "50-65", IF(AN4>65, "66+", "N") ))) -> 50-65 | AP4: 2166 | AQ4: 1 | AR4: 0 | AS4: 0 | AT4: 0 | AU4: 0 | AV4: 0 | AW4: 1 | AX4: 0 | AY4: 0 | AZ4: 4 | BA4: 42683 | BB4: =MONTH(BA4) -> 11 | BC4: =TEXT(BA4,"mmmm") -> November | BD4: 1 | BE4: =_xlfn.TEXTJOIN(",",TRUE,A4:AZ4) -> 2180,4861,Low income,2429,High spender,0.499691421518206,0,0,20,2,1,1,1,0,1,6,0.333333333333333,0.166666666666667,0.166666666666667,0.166666666666667,0,0.166666666666667,0,0,0,0,0,0,0,0,0,14,0,0,0,0,0,0,0,55,50-65,2166,1,0,0,0,0,0,1,0,0,4
A5: 1486 | B5: 33590 | C5: =IF(B5<=AVERAGE(B:B),"Low income", "High income") -> Low income | D5: 1892 | E5: =IF(D5<=AVERAGE(D:D),"Low spender", "High spender") -> High spender | F5: =D5/B5 -> 0.056326288 | G5: 2 | H5: 1 | I5: 65 | J5: 4 | K5: 0 | L5: 2 | M5: 0 | N5: 0 | O5: 2 | P5: =SUM(J5:O5) -> 8 | Q5: =IF(P5=0,0,J5/P5) -> 0.5 | R5: =IF(P5=0,0,K5/P5) -> 0 | S5: =IF(P5=0,0,L5/P5) -> 0.25 | T5: =IF(P5=0,0,M5/P5) -> 0 | U5: =IF(P5=0,0,N5/P5) -> 0 | V5: =IF(P5=0,0,O5/P5) -> 0.25 | W5: 1 | X5: 1 | Y5: 0 | Z5: 2 | AA5: =SUM(W5:Z5) -> 4 | AB5: =IF(AA5=0,0,W5/AA5) -> 0.25 | AC5: =IF(AA5=0,0,X5/AA5) -> 0.25 | AD5: =IF(AA5=0,0,Y5/AA5) -> 0 | AE5: =IF(AA5=0,0,Z5/AA5) -> 0.5 | AF5: 7 | AG5: 0 | AH5: 0 | AI5: 0 | AJ5: 0 | AK5: 0 | AL5: 0 | AM5: 0 | AN5: 46 | AO5: =IF(AND(AN5<36,AN5>23), "24-35", IF(AND(AN5<51,AN5>35), "36-50", IF(AND(AN5<66,AN5>50), "50-65", IF(AN5>65, "66+", "N") ))) -> 36-50 | AP5: 2397 | AQ5: 0 | AR5: 0 | AS5: 0 | AT5: 1 | AU5: 0 | AV5: 0 | AW5: 1 | AX5: 0 | AY5: 0 | AZ5: 4 | BA5: 42452 | BB5: =MONTH(BA5) -> 3 | BC5: =TEXT(BA5,"mmmm") -> March | BD5: 1 | BE5: =_xlfn.TEXTJOIN(",",TRUE,A5:AZ5) -> 1486,33590,Low income,1892,High spender,0.0563262875855909,2,1,65,4,0,2,0,0,2,8,0.5,0,0.25,0,0,0.25,1,1,0,2,4,0.25,0.25,0,0.5,7,0,0,0,0,0,0,0,46,36-50,2397,0,0,0,1,0,0,1,0,0,4
A6: 2082 | B6: 1730 | C6: =IF(B6<=AVERAGE(B:B),"Low income", "High income") -> Low income | D6: 66 | E6: =IF(D6<=AVERAGE(D:D),"Low spender", "High spender") -> Low spender | F6: =D6/B6 -> 0.038150289 | G6: 0 | H6: 0 | I6: 65 | J6: 1 | K6: 1 | L6: 3 | M6: 1 | N6: 1 | O6: 1 | P6: =SUM(J6:O6) -> 8 | Q6: =IF(P6=0,0,J6/P6) -> 0.125 | R6: =IF(P6=0,0,K6/P6) -> 0.125 | S6: =IF(P6=0,0,L6/P6) -> 0.375 | T6: =IF(P6=0,0,M6/P6) -> 0.125 | U6: =IF(P6=0,0,N6/P6) -> 0.125 | V6: =IF(P6=0,0,O6/P6) -> 0.125 | W6: 15 | X6: 0 | Y6: 0 | Z6: 0 | AA6: =SUM(W6:Z6) -> 15 | AB6: =IF(AA6=0,0,W6/AA6) -> 1 | AC6: =IF(AA6=0,0,X6/AA6) -> 0 | AD6: =IF(AA6=0,0,Y6/AA6) -> 0 | AE6: =IF(AA6=0,0,Z6/AA6) -> 0 | AF6: 20 | AG6: 0 | AH6: 0 | AI6: 0 | AJ6: 0 | AK6: 0 | AL6: 0 | AM6: 0 | AN6: 49 | AO6: =IF(AND(AN6<36,AN6>23), "24-35", IF(AND(AN6<51,AN6>35), "36-50", IF(AND(AN6<66,AN6>50), "50-65", IF(AN6>65, "66+", "N") ))) -> 36-50 | AP6: 2201 | AQ6: 1 | AR6: 0 | AS6: 0 | AT6: 0 | AU6: 0 | AV6: 0 | AW6: 1 | AX6: 0 | AY6: 0 | AZ6: 6 | BA6: 42648 | BB6: =MONTH(BA6) -> 10 | BC6: =TEXT(BA6,"mmmm") -> October | BD6: 1 | BE6: =_xlfn.TEXTJOIN(",",TRUE,A6:AZ6) -> 2082,1730,Low income,66,Low spender,0.038150289017341,0,0,65,1,1,3,1,1,1,8,0.125,0.125,0.375,0.125,0.125,0.125,15,0,0,0,15,1,0,0,0,20,0,0,0,0,0,0,0,49,36-50,2201,1,0,0,0,0,0,1,0,0,6
A7: 2186 | B7: 4023 | C7: =IF(B7<=AVERAGE(B:B),"Low income", "High income") -> Low income | D7: 2304 | E7: =IF(D7<=AVERAGE(D:D),"Low spender", "High spender") -> High spender | F7: =D7/B7 -> 0.57270694 | G7: 1 | H7: 1 | I7: 29 | J7: 5 | K7: 0 | L7: 1 | M7: 1 | N7: 1 | O7: 1 | P7: =SUM(J7:O7) -> 9 | Q7: =IF(P7=0,0,J7/P7) -> 0.55555556 | R7: =IF(P7=0,0,K7/P7) -> 0 | S7: =IF(P7=0,0,L7/P7) -> 0.11111111 | T7: =IF(P7=0,0,M7/P7) -> 0.11111111 | U7: =IF(P7=0,0,N7/P7) -> 0.11111111 | V7: =IF(P7=0,0,O7/P7) -> 0.11111111 | W7: 15 | X7: 0 | Y7: 0 | Z7: 0 | AA7: =SUM(W7:Z7) -> 15 | AB7: =IF(AA7=0,0,W7/AA7) -> 1 | AC7: =IF(AA7=0,0,X7/AA7) -> 0 | AD7: =IF(AA7=0,0,Y7/AA7) -> 0 | AE7: =IF(AA7=0,0,Z7/AA7) -> 0 | AF7: 19 | AG7: 0 | AH7: 0 | AI7: 0 | AJ7: 0 | AK7: 0 | AL7: 0 | AM7: 0 | AN7: 57 | AO7: =IF(AND(AN7<36,AN7>23), "24-35", IF(AND(AN7<51,AN7>35), "36-50", IF(AND(AN7<66,AN7>50), "50-65", IF(AN7>65, "66+", "N") ))) -> 50-65 | AP7: 2165 | AQ7: 0 | AR7: 1 | AS7: 0 | AT7: 0 | AU7: 0 | AV7: 0 | AW7: 0 | AX7: 0 | AY7: 1 | AZ7: 7 | BA7: 42684 | BB7: =MONTH(BA7) -> 11 | BC7: =TEXT(BA7,"mmmm") -> November | BD7: 1 | BE7: =_xlfn.TEXTJOIN(",",TRUE,A7:AZ7) -> 2186,4023,Low income,2304,High spender,0.572706935123042,1,1,29,5,0,1,1,1,1,9,0.555555555555556,0,0.111111111111111,0.111111111111111,0.111111111111111,0.111111111111111,15,0,0,0,15,1,0,0,0,19,0,0,0,0,0,0,0,57,50-65,2165,0,1,0,0,0,0,0,0,1,7
A8: 2161 | B8: 32583 | C8: =IF(B8<=AVERAGE(B:B),"Low income", "High income") -> Low income | D8: 1125 | E8: =IF(D8<=AVERAGE(D:D),"Low spender", "High spender") -> High spender | F8: =D8/B8 -> 0.034527207 | G8: 1 | H8: 1 | I8: 10 | J8: 5 | K8: 0 | L8: 3 | M8: 0 | N8: 0 | O8: 1 | P8: =SUM(J8:O8) -> 9 | Q8: =IF(P8=0,0,J8/P8) -> 0.55555556 | R8: =IF(P8=0,0,K8/P8) -> 0 | S8: =IF(P8=0,0,L8/P8) -> 0.33333333 | T8: =IF(P8=0,0,M8/P8) -> 0 | U8: =IF(P8=0,0,N8/P8) -> 0 | V8: =IF(P8=0,0,O8/P8) -> 0.11111111 | W8: 1 | X8: 1 | Y8: 0 | Z8: 2 | AA8: =SUM(W8:Z8) -> 4 | AB8: =IF(AA8=0,0,W8/AA8) -> 0.25 | AC8: =IF(AA8=0,0,X8/AA8) -> 0.25 | AD8: =IF(AA8=0,0,Y8/AA8) -> 0 | AE8: =IF(AA8=0,0,Z8/AA8) -> 0.5 | AF8: 7 | AG8: 0 | AH8: 0 | AI8: 0 | AJ8: 0 | AK8: 0 | AL8: 0 | AM8: 0 | AN8: 59 | AO8: =IF(AND(AN8<36,AN8>23), "24-35", IF(AND(AN8<51,AN8>35), "36-50", IF(AND(AN8<66,AN8>50), "50-65", IF(AN8>65, "66+", "N") ))) -> 50-65 | AP8: 2173 | AQ8: 0 | AR8: 0 | AS8: 0 | AT8: 1 | AU8: 0 | AV8: 0 | AW8: 0 | AX8: 0 | AY8: 1 | AZ8: 7 | BA8: 42676 | BB8: =MONTH(BA8) -> 11 | BC8: =TEXT(BA8,"mmmm") -> November | BD8: 1 | BE8: =_xlfn.TEXTJOIN(",",TRUE,A8:AZ8) -> 2161,32583,Low income,1125,High spender,0.0345272074394623,1,1,10,5,0,3,0,0,1,9,0.555555555555556,0,0.333333333333333,0,0,0.111111111111111,1,1,0,2,4,0.25,0.25,0,0.5,7,0,0,0,0,0,0,0,59,50-65,2173,0,0,0,1,0,0,0,0,1,7
A9: 1960 | B9: 34578 | C9: =IF(B9<=AVERAGE(B:B),"Low income", "High income") -> Low income | D9: 523 | E9: =IF(D9<=AVERAGE(D:D),"Low spender", "High spender") -> Low spender | F9: =D9/B9 -> 0.015125224 | G9: 2 | H9: 1 | I9: 1 | J9: 7 | K9: 0 | L9: 1 | M9: 0 | N9: 0 | O9: 0 | P9: =SUM(J9:O9) -> 8 | Q9: =IF(P9=0,0,J9/P9) -> 0.875 | R9: =IF(P9=0,0,K9/P9) -> 0 | S9: =IF(P9=0,0,L9/P9) -> 0.125 | T9: =IF(P9=0,0,M9/P9) -> 0 | U9: =IF(P9=0,0,N9/P9) -> 0 | V9: =IF(P9=0,0,O9/P9) -> 0 | W9: 1 | X9: 1 | Y9: 0 | Z9: 2 | AA9: =SUM(W9:Z9) -> 4 | AB9: =IF(AA9=0,0,W9/AA9) -> 0.25 | AC9: =IF(AA9=0,0,X9/AA9) -> 0.25 | AD9: =IF(AA9=0,0,Y9/AA9) -> 0 | AE9: =IF(AA9=0,0,Z9/AA9) -> 0.5 | AF9: 6 | AG9: 0 | AH9: 0 | AI9: 0 | AJ9: 0 | AK9: 0 | AL9: 0 | AM9: 0 | AN9: 48 | AO9: =IF(AND(AN9<36,AN9>23), "24-35", IF(AND(AN9<51,AN9>35), "36-50", IF(AND(AN9<66,AN9>50), "50-65", IF(AN9>65, "66+", "N") ))) -> 36-50 | AP9: 2238 | AQ9: 0 | AR9: 0 | AS9: 0 | AT9: 1 | AU9: 0 | AV9: 0 | AW9: 0 | AX9: 0 | AY9: 1 | AZ9: 8 | BA9: 42611 | BB9: =MONTH(BA9) -> 8 | BC9: =TEXT(BA9,"mmmm") -> August | BD9: 1 | BE9: =_xlfn.TEXTJOIN(",",TRUE,A9:AZ9) -> 1960,34578,Low income,523,Low spender,0.0151252241309503,2,1,1,7,0,1,0,0,0,8,0.875,0,0.125,0,0,0,1,1,0,2,4,0.25,0.25,0,0.5,6,0,0,0,0,0,0,0,48,36-50,2238,0,0,0,1,0,0,0,0,1,8
A10: 1794 | B10: 14421 | C10: =IF(B10<=AVERAGE(B:B),"Low income", "High income") -> Low income | D10: 17 | E10: =IF(D10<=AVERAGE(D:D),"Low spender", "High spender") -> Low spender | F10: =D10/B10 -> 0.0011788364 | G10: 0 | H10: 0 | I10: 81 | J10: 0 | K10: 0 | L10: 2 | M10: 3 | N10: 3 | O10: 8 | P10: =SUM(J10:O10) -> 16 | Q10: =IF(P10=0,0,J10/P10) -> 0 | R10: =IF(P10=0,0,K10/P10) -> 0 | S10: =IF(P10=0,0,L10/P10) -> 0.125 | T10: =IF(P10=0,0,M10/P10) -> 0.1875 | U10: =IF(P10=0,0,N10/P10) -> 0.1875 | V10: =IF(P10=0,0,O10/P10) -> 0.5 | W10: 1 | X10: 1 | Y10: 0 | Z10: 2 | AA10: =SUM(W10:Z10) -> 4 | AB10: =IF(AA10=0,0,W10/AA10) -> 0.25 | AC10: =IF(AA10=0,0,X10/AA10) -> 0.25 | AD10: =IF(AA10=0,0,Y10/AA10) -> 0 | AE10: =IF(AA10=0,0,Z10/AA10) -> 0.5 | AF10: 5 | AG10: 0 | AH10: 0 | AI10: 1 | AJ10: 0 | AK10: 0 | AL10: 0 | AM10: 0 | AN10: 24 | AO10: =IF(AND(AN10<36,AN10>23), "24-35", IF(AND(AN10<51,AN10>35), "36-50", IF(AND(AN10<66,AN10>50), "50-65", IF(AN10>65, "66+", "N") ))) -> 24-35 | AP10: 2291 | AQ10: 0 | AR10: 1 | AS10: 0 | AT10: 0 | AU10: 0 | AV10: 0 | AW10: 0 | AX10: 0 | AY10: 0 | AZ10: 0 | BA10: 42558 | BB10: =MONTH(BA10) -> 7 | BC10: =TEXT(BA10,"mmmm") -> July | BD10: 1 | BE10: =_xlfn.TEXTJOIN(",",TRUE,A10:AZ10) -> 1794,14421,Low income,17,Low spender,0.00117883641911102,0,0,81,0,0,2,3,3,8,16,0,0,0.125,0.1875,0.1875,0.5,1,1,0,2,4,0.25,0.25,0,0.5,5,0,0,1,0,0,0,0,24,24-35,2291,0,1,0,0,0,0,0,0,0,0
A11: 1606 | B11: 11448 | C11: =IF(B11<=AVERAGE(B:B),"Low income", "High income") -> Low income | D11: 348 | E11: =IF(D11<=AVERAGE(D:D),"Low spender", "High spender") -> Low spender | F11: =D11/B11 -> 0.030398323 | G11: 0 | H11: 0 | I11: 16 | J11: 0 | K11: 0 | L11: 0 | M11: 6 | N11: 2 | O11: 6 | P11: =SUM(J11:O11) -> 14 | Q11: =IF(P11=0,0,J11/P11) -> 0 | R11: =IF(P11=0,0,K11/P11) -> 0 | S11: =IF(P11=0,0,L11/P11) -> 0 | T11: =IF(P11=0,0,M11/P11) -> 0.42857143 | U11: =IF(P11=0,0,N11/P11) -> 0.14285714 | V11: =IF(P11=0,0,O11/P11) -> 0.42857143 | W11: 1 | X11: 1 | Y11: 0 | Z11: 2 | AA11: =SUM(W11:Z11) -> 4 | AB11: =IF(AA11=0,0,W11/AA11) -> 0.25 | AC11: =IF(AA11=0,0,X11/AA11) -> 0.25 | AD11: =IF(AA11=0,0,Y11/AA11) -> 0 | AE11: =IF(AA11=0,0,Z11/AA11) -> 0.5 | AF11: 6 | AG11: 0 | AH11: 0 | AI11: 0 | AJ11: 0 | AK11: 0 | AL11: 0 | AM11: 0 | AN11: 45 | AO11: =IF(AND(AN11<36,AN11>23), "24-35", IF(AND(AN11<51,AN11>35), "36-50", IF(AND(AN11<66,AN11>50), "50-65", IF(AN11>65, "66+", "N") ))) -> 36-50 | AP11: 2355 | AQ11: 1 | AR11: 0 | AS11: 0 | AT11: 0 | AU11: 0 | AV11: 1 | AW11: 0 | AX11: 0 | AY11: 0 | AZ11: 2 | BA11: 42494 | BB11: =MONTH(BA11) -> 5 | BC11: =TEXT(BA11,"mmmm") -> May | BD11: 1 | BE11: =_xlfn.TEXTJOIN(",",TRUE,A11:AZ11) -> 1606,11448,Low income,348,Low spender,0.030398322851153,0,0,16,0,0,0,6,2,6,14,0,0,0,0.428571428571429,0.142857142857143,0.428571428571429,1,1,0,2,4,0.25,0.25,0,0.5,6,0,0,0,0,0,0,0,45,36-50,2355,1,0,0,0,0,1,0,0,0,2
A12: 1201 | B12: 25176 | C12: =IF(B12<=AVERAGE(B:B),"Low income", "High income") -> Low income | D12: 1677 | E12: =IF(D12<=AVERAGE(D:D),"Low spender", "High spender") -> High spender | F12: =D12/B12 -> 0.066611058 | G12: 1 | H12: 1 | I12: 79 | J12: 4 | K12: 0 | L12: 4 | M12: 0 | N12: 0 | O12: 5 | P12: =SUM(J12:O12) -> 13 | Q12: =IF(P12=0,0,J12/P12) -> 0.30769231 | R12: =IF(P12=0,0,K12/P12) -> 0 | S12: =IF(P12=0,0,L12/P12) -> 0.30769231 | T12: =IF(P12=0,0,M12/P12) -> 0 | U12: =IF(P12=0,0,N12/P12) -> 0 | V12: =IF(P12=0,0,O12/P12) -> 0.38461538 | W12: 1 | X12: 1 | Y12: 0 | Z12: 2 | AA12: =SUM(W12:Z12) -> 4 | AB12: =IF(AA12=0,0,W12/AA12) -> 0.25 | AC12: =IF(AA12=0,0,X12/AA12) -> 0.25 | AD12: =IF(AA12=0,0,Y12/AA12) -> 0 | AE12: =IF(AA12=0,0,Z12/AA12) -> 0.5 | AF12: 7 | AG12: 0 | AH12: 0 | AI12: 0 | AJ12: 0 | AK12: 0 | AL12: 0 | AM12: 0 | AN12: 44 | AO12: =IF(AND(AN12<36,AN12>23), "24-35", IF(AND(AN12<51,AN12>35), "36-50", IF(AND(AN12<66,AN12>50), "50-65", IF(AN12>65, "66+", "N") ))) -> 36-50 | AP12: 2482 | AQ12: 0 | AR12: 0 | AS12: 0 | AT12: 1 | AU12: 0 | AV12: 1 | AW12: 0 | AX12: 0 | AY12: 0 | AZ12: 3 | BA12: 42367 | BB12: =MONTH(BA12) -> 12 | BC12: =TEXT(BA12,"mmmm") -> December | BD12: 1 | BE12: =_xlfn.TEXTJOIN(",",TRUE,A12:AZ12) -> 1201,25176,Low income,1677,High spender,0.0666110581506196,1,1,79,4,0,4,0,0,5,13,0.307692307692308,0,0.307692307692308,0,0,0.384615384615385,1,1,0,2,4,0.25,0.25,0,0.5,7,0,0,0,0,0,0,0,44,36-50,2482,0,0,0,1,0,1,0,0,0,3
A13: 1071 | B13: 30523 | C13: =IF(B13<=AVERAGE(B:B),"Low income", "High income") -> Low income | D13: 2304 | E13: =IF(D13<=AVERAGE(D:D),"Low spender", "High spender") -> High spender | F13: =D13/B13 -> 0.075484061 | G13: 2 | H13: 1 | I13: 0 | J13: 5 | K13: 0 | L13: 3 | M13: 0 | N13: 0 | O13: 5 | P13: =SUM(J13:O13) -> 13 | Q13: =IF(P13=0,0,J13/P13) -> 0.38461538 | R13: =IF(P13=0,0,K13/P13) -> 0 | S13: =IF(P13=0,0,L13/P13) -> 0.23076923 | T13: =IF(P13=0,0,M13/P13) -> 0 | U13: =IF(P13=0,0,N13/P13) -> 0 | V13: =IF(P13=0,0,O13/P13) -> 0.38461538 | W13: 1 | X13: 1 | Y13: 0 | Z13: 2 | AA13: =SUM(W13:Z13) -> 4 | AB13: =IF(AA13=0,0,W13/AA13) -> 0.25 | AC13: =IF(AA13=0,0,X13/AA13) -> 0.25 | AD13: =IF(AA13=0,0,Y13/AA13) -> 0 | AE13: =IF(AA13=0,0,Z13/AA13) -> 0.5 | AF13: 7 | AG13: 0 | AH13: 0 | AI13: 0 | AJ13: 0 | AK13: 0 | AL13: 0 | AM13: 0 | AN13: 62 | AO13: =IF(AND(AN13<36,AN13>23), "24-35", IF(AND(AN13<51,AN13>35), "36-50", IF(AND(AN13<66,AN13>50), "50-65", IF(AN13>65, "66+", "N") ))) -> 50-65 | AP13: 2522 | AQ13: 0 | AR13: 0 | AS13: 1 | AT13: 0 | AU13: 0 | AV13: 0 | AW13: 0 | AX13: 1 | AY13: 0 | AZ13: 3 | BA13: 42327 | BB13: =MONTH(BA13) -> 11 | BC13: =TEXT(BA13,"mmmm") -> November | BD13: 1 | BE13: =_xlfn.TEXTJOIN(",",TRUE,A13:AZ13) -> 1071,30523,Low income,2304,High spender,0.075484061199751,2,1,0,5,0,3,0,0,5,13,0.384615384615385,0,0.230769230769231,0,0,0.384615384615385,1,1,0,2,4,0.25,0.25,0,0.5,7,0,0,0,0,0,0,0,62,50-65,2522,0,0,1,0,0,0,0,1,0,3
... A2022: 1779 | B2022: 90638 | C2022: =IF(B2022<=AVERAGE(B:B),"Low income", "High income") -> High income | D2022: 40 | E2022: =IF(D2022<=AVERAGE(D:D),"Low spender", "High spender") -> Low spender | F2022: =D2022/B2022 -> 0.000441316 | G2022: 0 | H2022: 0 | I2022: 29 | J2022: 1156 | K2022: 120 | L2022: 915 | M2022: 94 | N2022: 144 | O2022: 96 | P2022: =SUM(J2022:O2022) -> 2525 | Q2022: =IF(P2022=0,0,J2022/P2022) -> 0.45782178 | R2022: =IF(P2022=0,0,K2022/P2022) -> 0.047524752 | S2022: =IF(P2022=0,0,L2022/P2022) -> 0.36237624 | T2022: =IF(P2022=0,0,M2022/P2022) -> 0.037227723 | U2022: =IF(P2022=0,0,N2022/P2022) -> 0.057029703 | V2022: =IF(P2022=0,0,O2022/P2022) -> 0.038019802 | W2022: 1 | X2022: 3 | Y2022: 4 | Z2022: 10 | AA2022: =SUM(W2022:Z2022) -> 18 | AB2022: =IF(AA2022=0,0,W2022/AA2022) -> 0.055555556 | AC2022: =IF(AA2022=0,0,X2022/AA2022) -> 0.16666667 | AD2022: =IF(AA2022=0,0,Y2022/AA2022) -> 0.22222222 | AE2022: =IF(AA2022=0,0,Z2022/AA2022) -> 0.55555556 | AF2022: 1 | AG2022: 0 | AH2022: 0 | AI2022: 0 | AJ2022: 0 | AK2022: 1 | AL2022: 0 | AM2022: 0 | AN2022: 29 | AO2022: =IF(AND(AN2022<36,AN2022>23), "24-35", IF(AND(AN2022<51,AN2022>35), "36-50", IF(AND(AN2022<66,AN2022>50), "50-65", IF(AN2022>65, "66+", "N") ))) -> 24-35 | AP2022: 2295 | AQ2022: 0 | AR2022: 0 | AS2022: 1 | AT2022: 0 | AU2022: 0 | AV2022: 0 | AW2022: 0 | AX2022: 1 | AY2022: 0 | AZ2022: 2333 | BA2022: 42554 | BB2022: =MONTH(BA2022) -> 7 | BC2022: =TEXT(BA2022,"mmmm") -> July | BD2022: 1 | BE2022: =_xlfn.TEXTJOIN(",",TRUE,A2022:AZ2022) -> 1779,90638,High income,40,Low spender,0.000441316004324897,0,0,29,1156,120,915,94,144,96,2525,0.457821782178218,0.0475247524752475,0.362376237623762,0.0372277227722772,0.057029702970297,0.038019801980198,1,3,4,10,18,0.0555555555555556,0.166666666666667,0.222222222222222,0.555555555555556,1,0,0,0,0,1,0,0,29,24-35,2295,0,0,1,0,0,0,0,1,0,2333

Sheet Summary
A6: Customer Overview
A7: Coluna1 | B7: Total Linhas | C7: Linhas para campanha 6 *
A8: Number of Customers | B8: =COUNT(Main!A:A) -> 2021 | C8: =SUBTOTAL(2,Main!A:A) -> 2021 | D8: NOTE*: | E8: Aqui tem o calculo total, e tem o calculo tendo em conta o filtro(=SubTotal)
A9: Oldest Customer | B9: =MAX(Main!AN:AN) -> 80 | C9: =SUBTOTAL(4,Main!AN:AN) -> 80
A10: Average Spent | B10: =AVERAGE(Main!D:D) -> 563.78921 | C10: =SUBTOTAL(1,Main!D:D) -> 563.78921 | D10: Customer Income Share: | E10: =((Tabela1[[#This Row],[Linhas para campanha 6 *]]-Tabela1[[#This Row],[Total Linhas]])/Tabela1[[#This Row],[Total Linhas]]) -> 0
A11: Total Spent | B11: =SUM(Main!D:D) -> 1139418 | C11: =SUBTOTAL(9,Main!D:D) -> 1139418
A12: Shortest Life Customer | B12: =MIN(Main!AP:AP) -> 2159 | C12: =SUBTOTAL(5,Main!AP:AP) -> 2159
A15: Spending-to-Income Ratio

Sheet Graphs
A1: Income | B1: Income Segment | C1: MntTotal | D1: Spending Segment
A2: 87679 | B2: =IF(A2<=AVERAGE(A:A),"Low income", "High income") -> High income | C2: 2491 | D2: =IF(C2<=AVERAGE(C:C),"Low Spender","High spender") -> High spender
A3: 52203 | B3: =IF(A3<=AVERAGE(A:A),"Low income", "High income") -> High income | C3: 911 | D3: =IF(C3<=AVERAGE(C:C),"Low Spender","High spender") -> High spender
A4: 90638 | B4: =IF(A4<=AVERAGE(A:A),"Low income", "High income") -> High income | C4: 2429 | D4: =IF(C4<=AVERAGE(C:C),"Low Spender","High spender") -> High spender
A5: 82576 | B5: =IF(A5<=AVERAGE(A:A),"Low income", "High income") -> High income | C5: 1892 | D5: =IF(C5<=AVERAGE(C:C),"Low Spender","High spender") -> High spender
A6: 7500 | B6: =IF(A6<=AVERAGE(A:A),"Low income", "High income") -> Low income | C6: 66 | D6: =IF(C6<=AVERAGE(C:C),"Low Spender","High spender") -> Low Spender
A7: 75759 | B7: =IF(A7<=AVERAGE(A:A),"Low income", "High income") -> High income | C7: 2304 | D7: =IF(C7<=AVERAGE(C:C),"Low Spender","High spender") -> High spender
A8: 75484 | B8: =IF(A8<=AVERAGE(A:A),"Low income", "High income") -> High income | C8: 1125 | D8: =IF(C8<=AVERAGE(C:C),"Low Spender","High spender") -> High spender
A9: 32632 | B9: =IF(A9<=AVERAGE(A:A),"Low income", "High income") -> Low income | C9: 523 | D9: =IF(C9<=AVERAGE(C:C),"Low Spender","High spender") -> Low Spender
A10: 27469 | B10: =IF(A10<=AVERAGE(A:A),"Low income", "High income") -> Low income | C10: 17 | D10: =IF(C10<=AVERAGE(C:C),"Low Spender","High spender") -> Low Spender | W10: =AVERAGE(C:C) -> 563.78921
A11: 49431 | B11: =IF(A11<=AVERAGE(A:A),"Low income", "High income") -> Low income | C11: 348 | D11: =IF(C11<=AVERAGE(C:C),"Low Spender","High spender") -> Low Spender
A12: 64176 | B12: =IF(A12<=AVERAGE(A:A),"Low income", "High income") -> High income | C12: 1677 | D12: =IF(C12<=AVERAGE(C:C),"Low Spender","High spender") -> High spender
A13: 93790 | B13: =IF(A13<=AVERAGE(A:A),"Low income", "High income") -> High income | C13: 2304 | D13: =IF(C13<=AVERAGE(C:C),"Low Spender","High spender") -> High spender
A14: 62972 | B14: =IF(A14<=AVERAGE(A:A),"Low income", "High income") -> High income | C14: 395 | D14: =IF(C14<=AVERAGE(C:C),"Low Spender","High spender") -> Low Spender
A15: 53230 | B15: =IF(A15<=AVERAGE(A:A),"Low income", "High income") -> High income | C15: 503 | D15: =IF(C15<=AVERAGE(C:C),"Low Spender","High spender") -> Low Spender
A16: 22304 | B16: =IF(A16<=AVERAGE(A:A),"Low income", "High income") -> Low income | C16: 16 | D16: =IF(C16<=AVERAGE(C:C),"Low Spender","High spender") -> Low Spender
A17: 91712 | B17: =IF(A17<=AVERAGE(A:A),"Low income", "High income") -> High income | C17: 2169 | D17: =IF(C17<=AVERAGE(C:C),"Low Spender","High spender") -> High spender
A18: 27683 | B18: =IF(A18<=AVERAGE(A:A),"Low income", "High income") -> Low income | C18: 306 | D18: =IF(C18<=AVERAGE(C:C),"Low Spender","High spender") -> Low Spender
A19: 36778 | B19: =IF(A19<=AVERAGE(A:A),"Low income", "High income") -> Low income | C19: 73 | D19: =IF(C19<=AVERAGE(C:C),"Low Spender","High spender") -> Low Spender
A20: 27203 | B20: =IF(A20<=AVERAGE(A:A),"Low income", "High income") -> Low income | C20: 40 | D20: =IF(C20<=AVERAGE(C:C),"Low Spender","High spender") -> Low Spender
A21: 43638 | B21: =IF(A21<=AVERAGE(A:A),"Low income", "High income") -> Low income | C21: 182 | D21: =IF(C21<=AVERAGE(C:C),"Low Spender","High spender") -> Low Spender
A22: 75825 | B22: =IF(A22<=AVERAGE(A:A),"Low income", "High income") -> High income | C22: 2158 | D22: =IF(C22<=AVERAGE(C:C),"Low Spender","High spender") -> High spender
... A2022: 35340 | B2022: =IF(A2022<=AVERAGE(A:A),"Low income", "High income") -> Low income | C2022: 40 | D2022: =IF(C2022<=AVERAGE(C:C),"Low Spender","High spender") -> Low Spender

Sheet Pivot Table
A3: Campaing 6? | B3: (Multiple Items)
A5: Age | B5: Contagem de MntTotal
A6: 24 | B6: 1
A7: 25 | B7: 1
A8: 26 | B8: 1
A9: 27 | B9: 2
A10: 28 | B10: 1
A11: 29 | B11: 4
A12: 30 | B12: 4
A13: 31 | B13: 1
A14: 32 | B14: 2
A15: 33 | B15: 5
A16: 34 | B16: 9
A17: 35 | B17: 4
... A59: 77 | B59: 1
A60: (blank)
A61: Grand Total | B61: 311

Sheet Pivot Table 2
A3: MonthName | B3: Nº Inscriptions
A4: January | B4: 204
A5: February | B5: 155
A6: March | B6: 201
A7: April | B7: 159
A8: May | B8: 162
A9: June | B9: 173
A10: July | B10: 189
A11: August | B11: 184
A12: September | B12: 186
A13: October | B13: 152
A14: November | B14: 131
A15: December | B15: 125
A16: (blank)
A17: Grand Total | B17: 2021

Sheet AcceptedCmp
A1: Column1 | B1: Percentagem de adesão | C1: Column22 | D1: Total Campaigns Accepted
A2: Cmp1 | B2: =(C2/2022) -> 0.065776459 | C2: =SUM(Main!AG:AG) -> 133 | D2: =SUM(Main!AG:AK) -> 611
A3: Cmp2 | B3: =(C3/2022) -> 0.012858556 | C3: =SUM(Main!AH:AH) -> 26 | D3: =SUM(Main!AG:AK) -> 611
A4: Cmp3 | B4: =(C4/2022) -> 0.074678536 | C4: =SUM(Main!AI:AI) -> 151 | D4: =SUM(Main!AG:AK) -> 611
A5: Cmp4 | B5: =(C5/2022) -> 0.076656775 | C5: =SUM(Main!AJ:AJ) -> 155 | D5: =SUM(Main!AG:AK) -> 611
A6: Cmp5 | B6: =(C6/2022) -> 0.072205737 | C6: =SUM(Main!AK:AK) -> 146 | D6: =SUM(Main!AG:AK) -> 611
A7: Cmp6 | B7: =(C7/2022) -> 0.15380811 | C7: =SUM(Main!AM:AM) -> 311 | D7: =SUM(Main!AG:AK) -> 611

Sheet ImpactCampaign
A3: AcceptedCmp1 | B3: Average of MntTotal | C3: Average of Income | G3: Campaign | H3: Avg Spending (Accepted) | I3: Avg Spending (Not Accepted) | J3: Spending Impact
A4: 0 | B4: 570.13347 | C4: 49777.639 | G4: Cmp1 | H4: 473.73 | I4: 570.13 | J4: =Table4[[#This Row],[Avg Spending (Accepted)]]-Table4[[#This Row],[Avg Spending (Not Accepted)]] -> -96.4
A5: 1 | B5: 473.72932 | C5: 78795.248 | G5: Cmp2 | H5: 418.15385 | I5: 565.68722 | J5: =Table4[[#This Row],[Avg Spending (Accepted)]]-Table4[[#This Row],[Avg Spending (Not Accepted)]] -> -147.53337
A6: (blank) | G6: Cmp3 | H6: 607.33775 | I6: 560.27273 | J6: =Table4[[#This Row],[Avg Spending (Accepted)]]-Table4[[#This Row],[Avg Spending (Not Accepted)]] -> 47.065021
A7: Grand Total | B7: 563.78921 | C7: 51687.259 | G7: Cmp4 | H7: 408.86452 | I7: 576.65809 | J7: =Table4[[#This Row],[Avg Spending (Accepted)]]-Table4[[#This Row],[Avg Spending (Not Accepted)]] -> -167.79358
G8: Cmp5 | H8: 446.14384 | I8: 572.94987 | J8: =Table4[[#This Row],[Avg Spending (Accepted)]]-Table4[[#This Row],[Avg Spending (Not Accepted)]] -> -126.80603
G9: Cmp6 | H9: 498.49518 | I9: 575.66433 | J9: =Table4[[#This Row],[Avg Spending (Accepted)]]-Table4[[#This Row],[Avg Spending (Not Accepted)]] -> -77.169151
A12: AcceptedCmp2 | B12: Average of MntTotal | C12: Average of Income
A13: 0 | B13: 565.68722 | C13: 51429.679
A14: 1 | B14: 418.15385 | C14: 71451.577
A15: (blank)
A16: Grand Total | B16: 563.78921 | C16: 51687.259
A20: AcceptedCmp3 | B20: Average of MntTotal | C20: Average of Income | J20: ...
A21: 0 | B21: 560.27273 | C21: 51759.076
A22: 1 | B22: 607.33775 | C22: 50797.868
A23: (blank)
A24: Grand Total | B24: 563.78921 | C24: 51687.259
A27: AcceptedCmp4 | B27: Average of MntTotal | C27: Average of Income
A28: 0 | B28: 576.65809 | C28: 50334.469
A29: 1 | B29: 408.86452 | C29: 67973.097
A30: (blank)
A31: Grand Total | B31: 563.78921 | C31: 51687.259
A33: AcceptedCmp5 | B33: Average of MntTotal | C33: Average of Income
A34: 0 | B34: 572.94987 | C34: 49290.655
A35: 1 | B35: 446.14384 | C35: 82465.562
A36: (blank)
A37: Grand Total | B37: 563.78921 | C37: 51687.259
A41: AcceptedCmp6 | B41: Average of MntTotal | C41: Average of Income
A42: 0 | B42: 575.66433 | C42: 50140.325
A43: 1 | B43: 498.49518 | C43: 60192.907
A44: (blank)
A45: Grand Total | B45: 563.78921 | C45: 51687.259

Sheet ProductDistribution
A1: MntWines | B1: MntFruits | C1: MntMeatProducts | D1: MntFishProducts | E1: MntSweetProducts | F1: MntGoldProds | G1: AcceptedCmp6
A2: 1259 | B2: 172 | C2: 815 | D2: 97 | E2: 148 | F2: 33 | G2: 1
A3: 2 | B3: 1 | C3: 1 | D3: 0 | E3: 0 | F3: 1 | G3: 0 | H3: Wines | I3: =SUM(A:A) -> 619421
A4: 2 | B4: 1 | C4: 1 | D4: 1 | E4: 0 | F4: 1 | G4: 0 | H4: Fruits | I4: =SUM(B:B) -> 53283
A5: 4 | B5: 0 | C5: 2 | D5: 0 | E5: 0 | F5: 2 | G5: 0 | H5: Meat | I5: =SUM(C:C) -> 335607
A6: 1 | B6: 1 | C6: 3 | D6: 1 | E6: 1 | F6: 1 | G6: 0 | H6: Fish | I6: =SUM(D:D) -> 75997
A7: 5 | B7: 0 | C7: 1 | D7: 1 | E7: 1 | F7: 1 | G7: 0 | H7: SweetProducts | I7: =SUM(E:E) -> 55110
A8: 5 | B8: 0 | C8: 3 | D8: 0 | E8: 0 | F8: 1 | G8: 0 | H8: GoldProducts | I8: =SUM(F:F) -> 88766
A9: 7 | B9: 0 | C9: 1 | D9: 0 | E9: 0 | F9: 0 | G9: 0 | H9: Total | I9: =SUM(I3:I8) -> 1228184
A10: 0 | B10: 0 | C10: 2 | D10: 3 | E10: 3 | F10: 8 | G10: 0
A11: 0 | B11: 0 | C11: 0 | D11: 6 | E11: 2 | F11: 6 | G11: 0
A12: 4 | B12: 0 | C12: 4 | D12: 0 | E12: 0 | F12: 5 | G12: 0
A13: 5 | B13: 0 | C13: 3 | D13: 0 | E13: 0 | F13: 5 | G13: 0
A14: 2 | B14: 0 | C14: 5 | D14: 2 | E14: 0 | F14: 1 | G14: 0 | H14: =CORREL(Main!B:B,A:A) -> 0.72470795
A15: 2 | B15: 2 | C15: 2 | D15: 2 | E15: 1 | F15: 1 | G15: 0
A16: 6 | B16: 0 | C16: 3 | D16: 0 | E16: 0 | F16: 1 | G16: 0
A17: 5 | B17: 0 | C17: 4 | D17: 0 | E17: 0 | F17: 1 | G17: 0
A18: 1 | B18: 0 | C18: 5 | D18: 0 | E18: 3 | F18: 9 | G18: 0
A19: 2 | B19: 2 | C19: 1 | D19: 3 | E19: 1 | F19: 2 | G19: 0
A20: 1 | B20: 1 | C20: 5 | D20: 0 | E20: 3 | F20: 1 | G20: 0 | H20: MntWines | I20: 153682
A21: 4 | B21: 0 | C21: 5 | D21: 0 | E21: 1 | F21: 5 | G21: 0 | H21: MntFruits | I21: 11901
A22: 6 | B22: 0 | C22: 4 | D22: 0 | E22: 0 | F22: 0 | G22: 0 | H22: MntMeatProducts | I22: 91874
A23: 6 | B23: 0 | C23: 2 | D23: 2 | E23: 0 | F23: 1 | G23: 0 | H23: MntFishProducts | I23: 15792
A24: 0 | B24: 2 | C24: 3 | D24: 4 | E24: 1 | F24: 5 | G24: 0 | H24: MntSweetProducts | I24: 12020
A25: 8 | B25: 0 | C25: 3 | D25: 0 | E25: 0 | F25: 1 | G25: 0 | H25: MntGoldProds | I25: 19479
A26: 10 | B26: 0 | C26: 1 | D26: 0 | E26: 0 | F26: 0 | G26: 0
A27: 6 | B27: 1 | C27: 2 | D27: 2 | E27: 0 | F27: 4 | G27: 0
A28: 8 | B28: 0 | C28: 3 | D28: 0 | E28: 0 | F28: 0 | G28: 0
A29: 2 | B29: 1 | C29: 4 | D29: 3 | E29: 1 | F29: 2 | G29: 0
A30: 6 | B30: 0 | C30: 5 | D30: 0 | E30: 0 | F30: 1 | G30: 0
A31: 4 | B31: 2 | C31: 5 | D31: 0 | E31: 0 | F31: 5 | G31: 0
A32: 0 | B32: 0 | C32: 1 | D32: 8 | E32: 3 | F32: 2 | G32: 0
A33: 9 | B33: 0 | C33: 3 | D33: 0 | E33: 0 | F33: 1 | G33: 0
A34: 9 | B34: 0 | C34: 3 | D34: 0 | E34: 0 | F34: 4 | G34: 0
A35: 1 | B35: 3 | C35: 4 | D35: 2 | E35: 2 | F35: 6 | G35: 0
A36: 4 | B36: 1 | C36: 5 | D36: 2 | E36: 0 | F36: 4 | G36: 0
A37: 0 | B37: 0 | C37: 1 | D37: 7 | E37: 4 | F37: 6 | G37: 0
... A172: 10 | B172: 0 | C172: 10 | D172: 3 | E172: 1 | F172: 7 | G172: 0
A173: 10 | B173: 0 | C173: 10 | D173: 3 | E173: 1 | F173: 7 | G173: 1 | I173: MntWines | J173: =SUBTOTAL(9,A:A) -> 619421
A174: 19 | B174: 0 | C174: 5 | D174: 0 | E174: 0 | F174: 8 | G174: 0
...

Sheet TotalSpendVsAgeGroup
A3: Row Labels | B3: Average of MntTotal
A4: 24-35 | B4: 607.4949
A5: 36-50 | B5: 601.39415
A6: 50-65 | B6: 543.19708
A7: 66+ | B7: 470.41053
A8: (blank)
A9: Grand Total | B9: 563.78921
A11: Age | B11: Average of MntTotal
A12: 24-35 | B12: 607.4949
A13: 36-50 | B13: 601.39415
A14: 50-65 | B14: 543.19708
A15: 66+ | B15: 470.41053

Sheet ChannelVsAgeSegm
A3: Row Labels | B3: Average of Pct_Deals | C3: Average of Pct_Web | D3: Average of Pct_Catalog | E3: Average of Pct_Store
A4: 24-35 | B4: 0.17018521 | C4: 0.24961984 | D4: 0.14089931 | E4: 0.43929565
A5: 36-50 | B5: 0.19660823 | C5: 0.27140888 | D5: 0.12263979 | E5: 0.4081735
A6: 50-65 | B6: 0.17602252 | C6: 0.26938711 | D6: 0.15147258 | E6: 0.40165793
A7: 66+ | B7: 0.15347606 | C7: 0.26947515 | D7: 0.1736443 | E7: 0.40340449
A8: (blank)
A9: Grand Total | B9: 0.18098587 | C9: 0.26833779 | D9: 0.14137587 | E9: 0.40831086
B12: Deals | C12: Web | D12: Catalog | E12: Store
A13: 24-35 | B13: 0.17018521 | C13: 0.24961984 | D13: 0.14089931 | E13: 0.43929565
A14: 36-50 | B14: 0.19660823 | C14: 0.27140888 | D14: 0.12263979 | E14: 0.4081735
A15: 50-65 | B15: 0.17602252 | C15: 0.26938711 | D15: 0.15147258 | E15: 0.40165793
A16: 66+ | B16: 0.15347606 | C16: 0.26947515 | D16: 0.1736443 | E16: 0.40340449

Sheet IncomeVsSpendingSegm
A3: Row Labels | B3: Sum of MntTotal
A4: High income | B4: 421224
A5: High spender | B5: 325105
A6: Low spender | B6: 96119
A7: Low income | B7: 718194
A8: High spender | B8: 627014
A9: Low spender | B9: 91180
A10: (blank)
A11: (blank)
A12: Grand Total | B12: 1139418
A16: High income | B16: 421224
A17: High spender | B17: 325105
A18: Low spender | B18: 96119
A19: Low income | B19: 718194
A20: High spender | B20: 627014
A21: Low spender | B21: 91180

Sheet ProductsVsIncome
A3: Row Labels | B3: Wines | C3: Fruits | D3: Meat | E3: Fish | F3: SweetProducts | G3: GoldProducts
A4: High income | B4: 0.52259556 | C4: 0.043503317 | D4: 0.25912932 | E4: 0.059740786 | F4: 0.046024954 | G4: 0.069006062
A5: Low income | B5: 0.39929798 | C5: 0.055167236 | D5: 0.23856648 | E5: 0.081581149 | F5: 0.0557558 | G5: 0.16963135
A6: (blank)
A7: Grand Total | B7: 0.4604282 | C7: 0.049384333 | D7: 0.24876142 | E7: 0.070752825 | F7: 0.050931303 | G7: 0.11974192

Sheet ID to Spent Tool
A4: Customer ID Input | B4: Total Spent by Customer
A5: 1153 | B5: =_xlfn.XLOOKUP(A5,Main!A:A,Main!D:D,"Not Found") -> 2491
